<sdf version='1.6'>
  <world name='default'>
    <light name='sun' type='directional'>
      <cast_shadows>1</cast_shadows>
      <pose frame=''>0 0 10 0 -0 0</pose>
      <diffuse>0.8 0.8 0.8 1</diffuse>
      <specular>0.2 0.2 0.2 1</specular>
      <attenuation>
        <range>1000</range>
        <constant>0.9</constant>
        <linear>0.01</linear>
        <quadratic>0.001</quadratic>
      </attenuation>
      <direction>-0.5 0.1 -0.9</direction>
    </light>
    <model name='ground_plane'>
      <static>1</static>
      <link name='link'>
        <collision name='collision'>
          <geometry>
            <plane>
              <normal>0 0 1</normal>
              <size>100 100</size>
            </plane>
          </geometry>
          <surface>
            <friction>
              <ode>
                <mu>100</mu>
                <mu2>50</mu2>
              </ode>
              <torsional>
                <ode/>
              </torsional>
            </friction>
            <contact>
              <ode/>
            </contact>
            <bounce/>
          </surface>
          <max_contacts>10</max_contacts>
        </collision>
        <visual name='visual'>
          <cast_shadows>0</cast_shadows>
          <geometry>
            <plane>
              <normal>0 0 1</normal>
              <size>100 100</size>
            </plane>
          </geometry>
          <material>
            <script>
              <uri>file://media/materials/scripts/gazebo.material</uri>
              <name>Gazebo/Grey</name>
            </script>
          </material>
        </visual>
        <self_collide>0</self_collide>
        <enable_wind>0</enable_wind>
        <kinematic>0</kinematic>
      </link>
    </model>
    <gravity>0 0 -9.8</gravity>
    <magnetic_field>6e-06 2.3e-05 -4.2e-05</magnetic_field>
    <atmosphere type='adiabatic'/>
    <physics name='default_physics' default='0' type='ode'>
      <max_step_size>0.001</max_step_size>
      <real_time_factor>1</real_time_factor>
      <real_time_update_rate>1000</real_time_update_rate>
    </physics>
    <scene>
      <ambient>0.4 0.4 0.4 1</ambient>
      <background>0.7 0.7 0.7 1</background>
      <shadows>1</shadows>
    </scene>
    <wind/>
    <spherical_coordinates>
      <surface_model>EARTH_WGS84</surface_model>
      <latitude_deg>0</latitude_deg>
      <longitude_deg>0</longitude_deg>
      <elevation>0</elevation>
      <heading_deg>0</heading_deg>
    </spherical_coordinates>
    <model name='unit_box'>
      <pose frame=''>3.00248 -2.35073 0.5 0 -0 0</pose>
      <link name='link'>
        <inertial>
          <mass>1</mass>
          <inertia>
            <ixx>0.166667</ixx>
            <ixy>0</ixy>
            <ixz>0</ixz>
            <iyy>0.166667</iyy>
            <iyz>0</iyz>
            <izz>0.166667</izz>
          </inertia>
          <pose frame=''>0 0 0 0 -0 0</pose>
        </inertial>
        <collision name='collision'>
          <geometry>
            <box>
              <size>1 1 1</size>
            </box>
          </geometry>
          <max_contacts>10</max_contacts>
          <surface>
            <contact>
              <ode/>
            </contact>
            <bounce/>
            <friction>
              <torsional>
                <ode/>
              </torsional>
              <ode/>
            </friction>
          </surface>
        </collision>
        <visual name='visual'>
          <geometry>
            <box>
              <size>1 1 1</size>
            </box>
          </geometry>
          <material>
            <script>
              <name>Gazebo/Grey</name>
              <uri>file://media/materials/scripts/gazebo.material</uri>
            </script>
          </material>
        </visual>
        <self_collide>0</self_collide>
        <enable_wind>0</enable_wind>
        <kinematic>0</kinematic>
      </link>
    </model>
    <model name='unit_cylinder'>
      <pose frame=''>5.88682 2.75848 0.5 0 -0 0</pose>
      <link name='link'>
        <inertial>
          <mass>1</mass>
          <inertia>
            <ixx>0.145833</ixx>
            <ixy>0</ixy>
            <ixz>0</ixz>
            <iyy>0.145833</iyy>
            <iyz>0</iyz>
            <izz>0.125</izz>
          </inertia>
          <pose frame=''>0 0 0 0 -0 0</pose>
        </inertial>
        <collision name='collision'>
          <geometry>
            <cylinder>
              <radius>0.5</radius>
              <length>1</length>
            </cylinder>
          </geometry>
          <max_contacts>10</max_contacts>
          <surface>
            <contact>
              <ode/>
            </contact>
            <bounce/>
            <friction>
              <torsional>
                <ode/>
              </torsional>
              <ode/>
            </friction>
          </surface>
        </collision>
        <visual name='visual'>
          <geometry>
            <cylinder>
              <radius>0.5</radius>
              <length>1</length>
            </cylinder>
          </geometry>
          <material>
            <script>
              <name>Gazebo/Grey</name>
              <uri>file://media/materials/scripts/gazebo.material</uri>
            </script>
          </material>
        </visual>
        <self_collide>0</self_collide>
        <enable_wind>0</enable_wind>
        <kinematic>0</kinematic>
      </link>
    </model>
    <model name='unit_sphere'>
      <pose frame=''>8.05866 -2.39867 0.5 0 -0 0</pose>
      <link name='link'>
        <inertial>
          <mass>1</mass>
          <inertia>
            <ixx>0.1</ixx>
            <ixy>0</ixy>
            <ixz>0</ixz>
            <iyy>0.1</iyy>
            <iyz>0</iyz>
            <izz>0.1</izz>
          </inertia>
          <pose frame=''>0 0 0 0 -0 0</pose>
        </inertial>
        <collision name='collision'>
          <geometry>
            <sphere>
              <radius>0.5</radius>
            </sphere>
          </geometry>
          <max_contacts>10</max_contacts>
          <surface>
            <contact>
              <ode/>
            </contact>
            <bounce/>
            <friction>
              <torsional>
                <ode/>
              </torsional>
              <ode/>
            </friction>
          </surface>
        </collision>
        <visual name='visual'>
          <geometry>
            <sphere>
              <radius>0.5</radius>
            </sphere>
          </geometry>
          <material>
            <script>
              <name>Gazebo/Grey</name>
              <uri>file://media/materials/scripts/gazebo.material</uri>
            </script>
          </material>
        </visual>
        <self_collide>0</self_collide>
        <enable_wind>0</enable_wind>
        <kinematic>0</kinematic>
      </link>
    </model>
    <state world_name='default'>
      <sim_time>120 737000000</sim_time>
      <real_time>74 433321403</real_time>
      <wall_time>1593667438 485766992</wall_time>
      <iterations>70873</iterations>
      <model name='TargetBot'>
        <pose frame=''>0.003757 0.000178 2e-06 7e-06 -1e-06 6e-06</pose>
        <scale>1 1 1</scale>
        <link name='chasis'>
          <pose frame=''>0.003757 0.000178 2e-06 7e-06 -1e-06 6e-06</pose>
          <velocity>5.5e-05 0.000175 -0.002475 0.007104 6e-06 1e-05</velocity>
          <acceleration>-0.004171 -4.27417 -4.94917 1.64226 0.01274 0.019785</acceleration>
          <wrench>-0.004171 -4.27425 -4.94927 0 -0 0</wrench>
        </link>
        <link name='left_front_wheel'>
          <pose frame=''>0.193755 0.290178 0.150005 1e-06 0.024506 6e-06</pose>
          <velocity>3.9e-05 -0.000927 -0.000399 0.006217 0.000255 8e-06</velocity>
          <acceleration>-0.040668 -1.86035 -0.798284 -0.132638 -0.274719 0.015958</acceleration>
          <wrench>-0.081335 -3.7207 -1.59657 0 -0 0</wrench>
        </link>
        <link name='left_rear_wheel'>
          <pose frame=''>-0.186244 0.290176 0.150005 2e-06 0.024459 7e-06</pose>
          <velocity>6.5e-05 -0.000934 -0.000399 0.00626 0.000421 2.2e-05</velocity>
          <acceleration>0.011134 -1.87339 -0.798958 -0.045423 0.057082 0.043779</acceleration>
          <wrench>0.022268 -3.74677 -1.59792 0 -0 0</wrench>
        </link>
        <link name='right_front_wheel'>
          <pose frame=''>0.193759 -0.289821 0.15 1.2e-05 0.009529 6e-06</pose>
          <velocity>7.5e-05 -0.000918 -0.004576 0.00619 1e-06 9e-06</velocity>
          <acceleration>0.030822 -1.84178 -9.15232 -0.185827 -0.294925 0.017985</acceleration>
          <wrench>0.061645 -3.68357 -18.3046 0 -0 0</wrench>
        </link>
        <link name='right_rear_wheel'>
          <pose frame=''>-0.186241 -0.289824 0.15 1.1e-05 0.010221 5e-06</pose>
          <velocity>6.2e-05 -0.000924 -0.004587 0.006228 -5.5e-05 1.6e-05</velocity>
          <acceleration>0.004335 -1.85359 -9.17362 -0.110111 -0.4402 0.031199</acceleration>
          <wrench>0.008669 -3.70717 -18.3472 0 -0 0</wrench>
        </link>
      </model>
      <model name='ground_plane'>
        <pose frame=''>0 0 0 0 -0 0</pose>
        <scale>1 1 1</scale>
        <link name='link'>
          <pose frame=''>0 0 0 0 -0 0</pose>
          <velocity>0 0 0 0 -0 0</velocity>
          <acceleration>0 0 0 0 -0 0</acceleration>
          <wrench>0 0 0 0 -0 0</wrench>
        </link>
      </model>
      <model name='unit_box'>
        <pose frame=''>3.00249 -2.35073 0.499995 1e-05 -0 0</pose>
        <scale>1 1 1</scale>
        <link name='link'>
          <pose frame=''>3.00249 -2.35073 0.499995 1e-05 -0 0</pose>
          <velocity>0 0 0 0 -0 0</velocity>
          <acceleration>-0.004709 -0.011055 -9.78158 0.022108 -0.009414 1e-06</acceleration>
          <wrench>-0.004709 -0.011055 -9.78158 0 -0 0</wrench>
        </link>
      </model>
      <model name='unit_cylinder'>
        <pose frame=''>5.88682 2.75848 0.499993 -3e-06 -3e-06 0</pose>
        <scale>1 1 1</scale>
        <link name='link'>
          <pose frame=''>5.88682 2.75848 0.499993 -3e-06 -3e-06 0</pose>
          <velocity>0 0 0 0 -0 0</velocity>
          <acceleration>0 0 -9.8 0 -0 0</acceleration>
          <wrench>0 0 -9.8 0 -0 0</wrench>
        </link>
      </model>
      <model name='unit_sphere'>
        <pose frame=''>8.05866 -2.39867 0.5 0 -0 0</pose>
        <scale>1 1 1</scale>
        <link name='link'>
          <pose frame=''>8.05866 -2.39867 0.5 0 -0 0</pose>
          <velocity>0 0 0 0 -0 0</velocity>
          <acceleration>0 0 0 0 -0 0</acceleration>
          <wrench>0 0 0 0 -0 0</wrench>
        </link>
      </model>
      <light name='sun'>
        <pose frame=''>0 0 10 0 -0 0</pose>
      </light>
    </state>
    <gui fullscreen='0'>
      <camera name='user_camera'>
        <pose frame=''>15.3561 -8.88372 8.00899 0 0.543643 2.33619</pose>
        <view_controller>orbit</view_controller>
        <projection_type>perspective</projection_type>
      </camera>
    </gui>
    <model name='TargetBot'>
      <link name='chasis'>
        <pose frame=''>0 0 0 0 -0 0</pose>
        <inertial>
          <pose frame=''>5e-06 0 0.325005 0 -0 0</pose>
          <mass>1.00002</mass>
          <inertia>
            <ixx>0.05582</ixx>
            <ixy>0</ixy>
            <ixz>-1.28497e-06</ixz>
            <iyy>0.0535463</iyy>
            <iyz>0</iyz>
            <izz>0.034545</izz>
          </inertia>
        </inertial>
        <collision name='chasis_collision'>
          <pose frame=''>0 0 0.325 0 -0 0</pose>
          <geometry>
            <box>
              <size>0.67 0.44 0.47</size>
            </box>
          </geometry>
          <surface>
            <contact>
              <ode/>
            </contact>
            <friction>
              <ode/>
              <torsional>
                <ode/>
              </torsional>
            </friction>
            <bounce/>
          </surface>
          <max_contacts>10</max_contacts>
        </collision>
        <collision name='chasis_fixed_joint_lump__imu_link_collision_1'>
          <pose frame=''>0.2 0 0.57 0 -0 0</pose>
          <geometry>
            <box>
              <size>0.08 0.06 0.01</size>
            </box>
          </geometry>
          <surface>
            <contact>
              <ode/>
            </contact>
            <friction>
              <ode/>
              <torsional>
                <ode/>
              </torsional>
            </friction>
            <bounce/>
          </surface>
          <max_contacts>10</max_contacts>
        </collision>
        <collision name='chasis_fixed_joint_lump__rplidar_link_collision_2'>
          <pose frame=''>0.3 0 0.59 0 -0 0</pose>
          <geometry>
            <cylinder>
              <length>0.04</length>
              <radius>0.035</radius>
            </cylinder>
          </geometry>
          <surface>
            <contact>
              <ode/>
            </contact>
            <friction>
              <ode/>
              <torsional>
                <ode/>
              </torsional>
            </friction>
            <bounce/>
          </surface>
          <max_contacts>10</max_contacts>
        </collision>
        <visual name='chasis_visual'>
          <pose frame=''>0 0 0.325 0 -0 0</pose>
          <geometry>
            <box>
              <size>0.67 0.44 0.47</size>
            </box>
          </geometry>
          <material>
            <script>
              <name>Gazebo/ZincYellow</name>
              <uri>file://media/materials/scripts/gazebo.material</uri>
            </script>
          </material>
        </visual>
        <visual name='chasis_fixed_joint_lump__imu_link_visual_1'>
          <pose frame=''>0.2 0 0.57 0 -0 0</pose>
          <geometry>
            <box>
              <size>0.08 0.06 0.01</size>
            </box>
          </geometry>
          <material>
            <script>
              <name>Gazebo/Blue</name>
              <uri>file://media/materials/scripts/gazebo.material</uri>
            </script>
          </material>
        </visual>
        <visual name='chasis_fixed_joint_lump__rplidar_link_visual_2'>
          <pose frame=''>0.3 0 0.59 0 -0 0</pose>
          <geometry>
            <cylinder>
              <length>0.04</length>
              <radius>0.035</radius>
            </cylinder>
          </geometry>
          <material>
            <script>
              <name>Gazebo/DarkGrey</name>
              <uri>file://media/materials/scripts/gazebo.material</uri>
            </script>
          </material>
        </visual>
        <velocity_decay/>
        <velocity_decay/>
        <sensor name='imu_sensor' type='imu'>
          <always_on>1</always_on>
          <update_rate>100</update_rate>
          <visualize>1</visualize>
          <topic>__default_topic__</topic>
          <plugin name='imu_plugin' filename='libgazebo_ros_imu_sensor.so'>
            <topicName>imu</topicName>
            <bodyName>imu_link</bodyName>
            <updateRateHZ>10.0</updateRateHZ>
            <gaussianNoise>0.0</gaussianNoise>
            <xyzOffset>0 0 0</xyzOffset>
            <rpyOffset>0 0 0</rpyOffset>
            <frameName>imu_link</frameName>
            <initialOrientationAsReference>false</initialOrientationAsReference>
            <robotNamespace>/</robotNamespace>
          </plugin>
          <pose frame=''>0.2 0 0.57 0 -0 0</pose>
        </sensor>
        <gravity>1</gravity>
        <velocity_decay/>
        <gravity>1</gravity>
        <velocity_decay/>
        <sensor name='head_hokuyo_sensor' type='ray'>
          <visualize>1</visualize>
          <update_rate>40</update_rate>
          <ray>
            <scan>
              <horizontal>
                <samples>720</samples>
                <resolution>1</resolution>
                <min_angle>-3.14159</min_angle>
                <max_angle>3.14159</max_angle>
              </horizontal>
              <vertical>
                <samples>1</samples>
                <min_angle>0</min_angle>
                <max_angle>0</max_angle>
              </vertical>
            </scan>
            <range>
              <min>0.1</min>
              <max>30</max>
              <resolution>0.01</resolution>
            </range>
            <noise>
              <type>gaussian</type>
              <mean>0</mean>
              <stddev>0.01</stddev>
            </noise>
          </ray>
          <plugin name='gazebo_ros_head_hokuyo_controller' filename='libgazebo_ros_laser.so'>
            <topicName>/laser/scan</topicName>
            <frameName>hokuyo_link</frameName>
            <robotNamespace>/</robotNamespace>
          </plugin>
          <pose frame=''>0.3 0 0.59 0 -0 0</pose>
        </sensor>
        <self_collide>0</self_collide>
        <kinematic>0</kinematic>
      </link>
      <link name='left_front_wheel'>
        <pose frame=''>0.19 0.29 0.15 0 -0 0</pose>
        <inertial>
          <pose frame=''>0 0 0 1.5707 -0 0</pose>
          <mass>2</mass>
          <inertia>
            <ixx>0.0129167</ixx>
            <ixy>0</ixy>
            <ixz>0</ixz>
            <iyy>0.0129167</iyy>
            <iyz>0</iyz>
            <izz>0.00050625</izz>
          </inertia>
        </inertial>
        <collision name='left_front_wheel_collision'>
          <pose frame=''>0 0 0 1.5707 -0 0</pose>
          <geometry>
            <cylinder>
              <length>0.1</length>
              <radius>0.15</radius>
            </cylinder>
          </geometry>
          <surface>
            <contact>
              <ode/>
            </contact>
            <friction>
              <ode/>
              <torsional>
                <ode/>
              </torsional>
            </friction>
            <bounce/>
          </surface>
          <max_contacts>10</max_contacts>
        </collision>
        <visual name='left_front_wheel_visual'>
          <pose frame=''>0 0 0 1.5707 -0 0</pose>
          <geometry>
            <cylinder>
              <length>0.1</length>
              <radius>0.15</radius>
            </cylinder>
          </geometry>
          <material>
            <script>
              <name>Gazebo/DarkGrey</name>
              <uri>file://media/materials/scripts/gazebo.material</uri>
            </script>
          </material>
        </visual>
        <gravity>1</gravity>
        <velocity_decay/>
        <self_collide>0</self_collide>
        <kinematic>0</kinematic>
      </link>
      <joint name='left_front_wheel_to_chasis' type='revolute'>
        <child>left_front_wheel</child>
        <parent>chasis</parent>
        <axis>
          <xyz>0 1 0</xyz>
          <limit>
            <lower>-1e+16</lower>
            <upper>1e+16</upper>
          </limit>
          <dynamics>
            <spring_reference>0</spring_reference>
            <spring_stiffness>0</spring_stiffness>
          </dynamics>
          <use_parent_model_frame>1</use_parent_model_frame>
        </axis>
      </joint>
      <link name='left_rear_wheel'>
        <pose frame=''>-0.19 0.29 0.15 0 -0 0</pose>
        <inertial>
          <pose frame=''>0 0 0 1.5707 -0 0</pose>
          <mass>2</mass>
          <inertia>
            <ixx>0.0129167</ixx>
            <ixy>0</ixy>
            <ixz>0</ixz>
            <iyy>0.0129167</iyy>
            <iyz>0</iyz>
            <izz>0.00050625</izz>
          </inertia>
        </inertial>
        <collision name='left_rear_wheel_collision'>
          <pose frame=''>0 0 0 1.5707 -0 0</pose>
          <geometry>
            <cylinder>
              <length>0.1</length>
              <radius>0.15</radius>
            </cylinder>
          </geometry>
          <surface>
            <contact>
              <ode/>
            </contact>
            <friction>
              <ode/>
              <torsional>
                <ode/>
              </torsional>
            </friction>
            <bounce/>
          </surface>
          <max_contacts>10</max_contacts>
        </collision>
        <visual name='left_rear_wheel_visual'>
          <pose frame=''>0 0 0 1.5707 -0 0</pose>
          <geometry>
            <cylinder>
              <length>0.1</length>
              <radius>0.15</radius>
            </cylinder>
          </geometry>
          <material>
            <script>
              <name>Gazebo/DarkGrey</name>
              <uri>file://media/materials/scripts/gazebo.material</uri>
            </script>
          </material>
        </visual>
        <gravity>1</gravity>
        <velocity_decay/>
        <self_collide>0</self_collide>
        <kinematic>0</kinematic>
      </link>
      <joint name='left_rear_wheel_to_chasis' type='revolute'>
        <child>left_rear_wheel</child>
        <parent>chasis</parent>
        <axis>
          <xyz>0 1 0</xyz>
          <limit>
            <lower>-1e+16</lower>
            <upper>1e+16</upper>
          </limit>
          <dynamics>
            <spring_reference>0</spring_reference>
            <spring_stiffness>0</spring_stiffness>
          </dynamics>
          <use_parent_model_frame>1</use_parent_model_frame>
        </axis>
      </joint>
      <link name='right_front_wheel'>
        <pose frame=''>0.19 -0.29 0.15 0 -0 0</pose>
        <inertial>
          <pose frame=''>0 0 0 1.5707 -0 0</pose>
          <mass>2</mass>
          <inertia>
            <ixx>0.0129167</ixx>
            <ixy>0</ixy>
            <ixz>0</ixz>
            <iyy>0.0129167</iyy>
            <iyz>0</iyz>
            <izz>0.00050625</izz>
          </inertia>
        </inertial>
        <collision name='right_front_wheel_collision'>
          <pose frame=''>0 0 0 1.5707 -0 0</pose>
          <geometry>
            <cylinder>
              <length>0.1</length>
              <radius>0.15</radius>
            </cylinder>
          </geometry>
          <surface>
            <contact>
              <ode/>
            </contact>
            <friction>
              <ode/>
              <torsional>
                <ode/>
              </torsional>
            </friction>
            <bounce/>
          </surface>
          <max_contacts>10</max_contacts>
        </collision>
        <visual name='right_front_wheel_visual'>
          <pose frame=''>0 0 0 1.5707 -0 0</pose>
          <geometry>
            <cylinder>
              <length>0.1</length>
              <radius>0.15</radius>
            </cylinder>
          </geometry>
          <material>
            <script>
              <name>Gazebo/DarkGrey</name>
              <uri>file://media/materials/scripts/gazebo.material</uri>
            </script>
          </material>
        </visual>
        <gravity>1</gravity>
        <velocity_decay/>
        <self_collide>0</self_collide>
        <kinematic>0</kinematic>
      </link>
      <joint name='right_front_wheel_to_chasis' type='revolute'>
        <child>right_front_wheel</child>
        <parent>chasis</parent>
        <axis>
          <xyz>0 1 0</xyz>
          <limit>
            <lower>-1e+16</lower>
            <upper>1e+16</upper>
          </limit>
          <dynamics>
            <spring_reference>0</spring_reference>
            <spring_stiffness>0</spring_stiffness>
          </dynamics>
          <use_parent_model_frame>1</use_parent_model_frame>
        </axis>
      </joint>
      <link name='right_rear_wheel'>
        <pose frame=''>-0.19 -0.29 0.15 0 -0 0</pose>
        <inertial>
          <pose frame=''>0 0 0 1.5707 -0 0</pose>
          <mass>2</mass>
          <inertia>
            <ixx>0.0129167</ixx>
            <ixy>0</ixy>
            <ixz>0</ixz>
            <iyy>0.0129167</iyy>
            <iyz>0</iyz>
            <izz>0.00050625</izz>
          </inertia>
        </inertial>
        <collision name='right_rear_wheel_collision'>
          <pose frame=''>0 0 0 1.5707 -0 0</pose>
          <geometry>
            <cylinder>
              <length>0.1</length>
              <radius>0.15</radius>
            </cylinder>
          </geometry>
          <surface>
            <contact>
              <ode/>
            </contact>
            <friction>
              <ode/>
              <torsional>
                <ode/>
              </torsional>
            </friction>
            <bounce/>
          </surface>
          <max_contacts>10</max_contacts>
        </collision>
        <visual name='right_rear_wheel_visual'>
          <pose frame=''>0 0 0 1.5707 -0 0</pose>
          <geometry>
            <cylinder>
              <length>0.1</length>
              <radius>0.15</radius>
            </cylinder>
          </geometry>
          <material>
            <script>
              <name>Gazebo/DarkGrey</name>
              <uri>file://media/materials/scripts/gazebo.material</uri>
            </script>
          </material>
        </visual>
        <gravity>1</gravity>
        <velocity_decay/>
        <self_collide>0</self_collide>
        <kinematic>0</kinematic>
      </link>
      <joint name='right_rear_wheel_to_chasis' type='revolute'>
        <child>right_rear_wheel</child>
        <parent>chasis</parent>
        <axis>
          <xyz>0 1 0</xyz>
          <limit>
            <lower>-1e+16</lower>
            <upper>1e+16</upper>
          </limit>
          <dynamics>
            <spring_reference>0</spring_reference>
            <spring_stiffness>0</spring_stiffness>
          </dynamics>
          <use_parent_model_frame>1</use_parent_model_frame>
        </axis>
      </joint>
      <static>0</static>
      <plugin name='skid_steer_drive_controller' filename='libgazebo_ros_skid_steer_drive.so'>
        <updateRate>100.0</updateRate>
        <robotNamespace>/</robotNamespace>
        <leftFrontJoint>left_front_wheel_to_chasis</leftFrontJoint>
        <rightFrontJoint>right_front_wheel_to_chasis</rightFrontJoint>
        <leftRearJoint>left_rear_wheel_to_chasis</leftRearJoint>
        <rightRearJoint>right_rear_wheel_to_chasis</rightRearJoint>
        <wheelSeparation>0.58</wheelSeparation>
        <wheelDiameter>0.3</wheelDiameter>
        <robotBaseFrame>chasis</robotBaseFrame>
        <torque>20</torque>
        <topicName>cmd_vel</topicName>
        <broadcastTF>false</broadcastTF>
      </plugin>
      <pose frame=''>0 0 1 0 -0 0</pose>
    </model>
  </world>
</sdf>
